list index out of range
list index out of range
list index out of range
list index out of range
Internal Server Error: /main/question/1/
Traceback (most recent call last):
  File "C:\Users\admin\p3\lib\site-packages\django\core\handlers\exception.py", line 41, in inner
    response = get_response(request)
  File "C:\Users\admin\p3\lib\site-packages\django\core\handlers\base.py", line 217, in _get_response
    response = self.process_exception_by_middleware(e, request)
  File "C:\Users\admin\p3\lib\site-packages\django\core\handlers\base.py", line 215, in _get_response
    response = response.render()
  File "C:\Users\admin\p3\lib\site-packages\django\template\response.py", line 107, in render
    self.content = self.rendered_content
  File "C:\Users\admin\p3\lib\site-packages\django\template\response.py", line 84, in rendered_content
    content = template.render(context, self._request)
  File "C:\Users\admin\p3\lib\site-packages\django\template\backends\django.py", line 66, in render
    return self.template.render(context)
  File "C:\Users\admin\p3\lib\site-packages\django\template\base.py", line 207, in render
    return self._render(context)
  File "C:\Users\admin\p3\lib\site-packages\django\test\utils.py", line 107, in instrumented_test_render
    return self.nodelist.render(context)
  File "C:\Users\admin\p3\lib\site-packages\django\template\base.py", line 990, in render
    bit = node.render_annotated(context)
  File "C:\Users\admin\p3\lib\site-packages\django\template\base.py", line 957, in render_annotated
    return self.render(context)
  File "C:\Users\admin\p3\lib\site-packages\django\template\defaulttags.py", line 458, in render
    url = reverse(view_name, args=args, kwargs=kwargs, current_app=current_app)
  File "C:\Users\admin\p3\lib\site-packages\django\urls\base.py", line 91, in reverse
    return force_text(iri_to_uri(resolver._reverse_with_prefix(view, prefix, *args, **kwargs)))
  File "C:\Users\admin\p3\lib\site-packages\django\urls\resolvers.py", line 497, in _reverse_with_prefix
    raise NoReverseMatch(msg)
django.urls.exceptions.NoReverseMatch: Reverse for 'add_choice' not found. 'add_choice' is not a valid view function or pattern name.
"GET /main/question/1/ HTTP/1.1" 500 123457
list index out of range
list index out of range
list index out of range
list index out of range
